Workbook

Sheet Summary
A1: YT Transcriber — Financial Model
A2: Edit Assumptions sheet (yellow cells) to update all figures automatically | 13 June 2026
A4: EXPLORER TIER — Free trial (3 videos) | Revenue: £0 | Shows cost of running free/trial users
A5: Users | B5: Monthly Revenue | C5: Total Costs | D5: Net Profit | E5: Margin | F5: Annual Profit | G5: Status
A6: 1 | B6: =0 | C6: =Assumptions!$B$20+A6*Assumptions!$B$23+A6*Assumptions!$B$24 | D6: =B6-C6 | E6: =IF(B6>0,D6/B6,0) | F6: =D6*12 | G6: =IF(D6<0,"Loss",IF(D6<20,"Break-even",IF(D6<500,"Growing","Profitable")))
A7: 5 | B7: =0 | C7: =Assumptions!$B$20+A7*Assumptions!$B$23+A7*Assumptions!$B$24 | D7: =B7-C7 | E7: =IF(B7>0,D7/B7,0) | F7: =D7*12 | G7: =IF(D7<0,"Loss",IF(D7<20,"Break-even",IF(D7<500,"Growing","Profitable")))
A8: 10 | B8: =0 | C8: =Assumptions!$B$20+A8*Assumptions!$B$23+A8*Assumptions!$B$24 | D8: =B8-C8 | E8: =IF(B8>0,D8/B8,0) | F8: =D8*12 | G8: =IF(D8<0,"Loss",IF(D8<20,"Break-even",IF(D8<500,"Growing","Profitable")))
A9: 15 | B9: =0 | C9: =Assumptions!$B$20+A9*Assumptions!$B$23+A9*Assumptions!$B$24 | D9: =B9-C9 | E9: =IF(B9>0,D9/B9,0) | F9: =D9*12 | G9: =IF(D9<0,"Loss",IF(D9<20,"Break-even",IF(D9<500,"Growing","Profitable")))
A10: 20 | B10: =0 | C10: =Assumptions!$B$20+A10*Assumptions!$B$23+A10*Assumptions!$B$24 | D10: =B10-C10 | E10: =IF(B10>0,D10/B10,0) | F10: =D10*12 | G10: =IF(D10<0,"Loss",IF(D10<20,"Break-even",IF(D10<500,"Growing","Profitable")))
A11: 50 | B11: =0 | C11: =Assumptions!$B$20+A11*Assumptions!$B$23+A11*Assumptions!$B$24 | D11: =B11-C11 | E11: =IF(B11>0,D11/B11,0) | F11: =D11*12 | G11: =IF(D11<0,"Loss",IF(D11<20,"Break-even",IF(D11<500,"Growing","Profitable")))
A12: 100 | B12: =0 | C12: =Assumptions!$B$20+A12*Assumptions!$B$23+A12*Assumptions!$B$24 | D12: =B12-C12 | E12: =IF(B12>0,D12/B12,0) | F12: =D12*12 | G12: =IF(D12<0,"Loss",IF(D12<20,"Break-even",IF(D12<500,"Growing","Profitable")))
A13: 200 | B13: =0 | C13: =Assumptions!$B$20+A13*Assumptions!$B$23+A13*Assumptions!$B$24 | D13: =B13-C13 | E13: =IF(B13>0,D13/B13,0) | F13: =D13*12 | G13: =IF(D13<0,"Loss",IF(D13<20,"Break-even",IF(D13<500,"Growing","Profitable")))
A14: 500 | B14: =0 | C14: =Assumptions!$B$20+A14*Assumptions!$B$23+A14*Assumptions!$B$24 | D14: =B14-C14 | E14: =IF(B14>0,D14/B14,0) | F14: =D14*12 | G14: =IF(D14<0,"Loss",IF(D14<20,"Break-even",IF(D14<500,"Growing","Profitable")))
A15: 1000 | B15: =0 | C15: =Assumptions!$B$20+A15*Assumptions!$B$23+A15*Assumptions!$B$24 | D15: =B15-C15 | E15: =IF(B15>0,D15/B15,0) | F15: =D15*12 | G15: =IF(D15<0,"Loss",IF(D15<20,"Break-even",IF(D15<500,"Growing","Profitable")))
A16: 2000 | B16: =0 | C16: =Assumptions!$B$20+A16*Assumptions!$B$23+A16*Assumptions!$B$24 | D16: =B16-C16 | E16: =IF(B16>0,D16/B16,0) | F16: =D16*12 | G16: =IF(D16<0,"Loss",IF(D16<20,"Break-even",IF(D16<500,"Growing","Profitable")))
A17: 5000 | B17: =0 | C17: =Assumptions!$B$20+A17*Assumptions!$B$23+A17*Assumptions!$B$24 | D17: =B17-C17 | E17: =IF(B17>0,D17/B17,0) | F17: =D17*12 | G17: =IF(D17<0,"Loss",IF(D17<20,"Break-even",IF(D17<500,"Growing","Profitable")))
A19: BLENDED MIX — Paying users: 20% Creator / 55% Studio / 25% Enterprise (adjust in Assumptions)
A20: Users | B20: Monthly Revenue | C20: Total Costs | D20: Net Profit | E20: Margin | F20: Annual Profit | G20: Status
A21: 1 | B21: =A21*Assumptions!$B$14 | C21: =Assumptions!$B$20+B21*Assumptions!$B$33+A21*Assumptions!$B$34+A21*Assumptions!$B$40+A21*Assumptions!$B$41 | D21: =B21-C21 | E21: =IF(B21>0,D21/B21,0) | F21: =D21*12 | G21: =IF(D21<0,"Loss",IF(D21<20,"Break-even",IF(D21<500,"Growing","Profitable")))
A22: 5 | B22: =A22*Assumptions!$B$14 | C22: =Assumptions!$B$20+B22*Assumptions!$B$33+A22*Assumptions!$B$34+A22*Assumptions!$B$40+A22*Assumptions!$B$41 | D22: =B22-C22 | E22: =IF(B22>0,D22/B22,0) | F22: =D22*12 | G22: =IF(D22<0,"Loss",IF(D22<20,"Break-even",IF(D22<500,"Growing","Profitable")))
A23: 10 | B23: =A23*Assumptions!$B$14 | C23: =Assumptions!$B$20+B23*Assumptions!$B$33+A23*Assumptions!$B$34+A23*Assumptions!$B$40+A23*Assumptions!$B$41 | D23: =B23-C23 | E23: =IF(B23>0,D23/B23,0) | F23: =D23*12 | G23: =IF(D23<0,"Loss",IF(D23<20,"Break-even",IF(D23<500,"Growing","Profitable")))
A24: 15 | B24: =A24*Assumptions!$B$14 | C24: =Assumptions!$B$20+B24*Assumptions!$B$33+A24*Assumptions!$B$34+A24*Assumptions!$B$40+A24*Assumptions!$B$41 | D24: =B24-C24 | E24: =IF(B24>0,D24/B24,0) | F24: =D24*12 | G24: =IF(D24<0,"Loss",IF(D24<20,"Break-even",IF(D24<500,"Growing","Profitable")))
A25: 20 | B25: =A25*Assumptions!$B$14 | C25: =Assumptions!$B$20+B25*Assumptions!$B$33+A25*Assumptions!$B$34+A25*Assumptions!$B$40+A25*Assumptions!$B$41 | D25: =B25-C25 | E25: =IF(B25>0,D25/B25,0) | F25: =D25*12 | G25: =IF(D25<0,"Loss",IF(D25<20,"Break-even",IF(D25<500,"Growing","Profitable")))
A26: 50 | B26: =A26*Assumptions!$B$14 | C26: =Assumptions!$B$20+B26*Assumptions!$B$33+A26*Assumptions!$B$34+A26*Assumptions!$B$40+A26*Assumptions!$B$41 | D26: =B26-C26 | E26: =IF(B26>0,D26/B26,0) | F26: =D26*12 | G26: =IF(D26<0,"Loss",IF(D26<20,"Break-even",IF(D26<500,"Growing","Profitable")))
A27: 100 | B27: =A27*Assumptions!$B$14 | C27: =Assumptions!$B$20+B27*Assumptions!$B$33+A27*Assumptions!$B$34+A27*Assumptions!$B$40+A27*Assumptions!$B$41 | D27: =B27-C27 | E27: =IF(B27>0,D27/B27,0) | F27: =D27*12 | G27: =IF(D27<0,"Loss",IF(D27<20,"Break-even",IF(D27<500,"Growing","Profitable")))
A28: 200 | B28: =A28*Assumptions!$B$14 | C28: =Assumptions!$B$20+B28*Assumptions!$B$33+A28*Assumptions!$B$34+A28*Assumptions!$B$40+A28*Assumptions!$B$41 | D28: =B28-C28 | E28: =IF(B28>0,D28/B28,0) | F28: =D28*12 | G28: =IF(D28<0,"Loss",IF(D28<20,"Break-even",IF(D28<500,"Growing","Profitable")))
A29: 500 | B29: =A29*Assumptions!$B$14 | C29: =Assumptions!$B$20+B29*Assumptions!$B$33+A29*Assumptions!$B$34+A29*Assumptions!$B$40+A29*Assumptions!$B$41 | D29: =B29-C29 | E29: =IF(B29>0,D29/B29,0) | F29: =D29*12 | G29: =IF(D29<0,"Loss",IF(D29<20,"Break-even",IF(D29<500,"Growing","Profitable")))
A30: 1000 | B30: =A30*Assumptions!$B$14 | C30: =Assumptions!$B$20+B30*Assumptions!$B$33+A30*Assumptions!$B$34+A30*Assumptions!$B$40+A30*Assumptions!$B$41 | D30: =B30-C30 | E30: =IF(B30>0,D30/B30,0) | F30: =D30*12 | G30: =IF(D30<0,"Loss",IF(D30<20,"Break-even",IF(D30<500,"Growing","Profitable")))
A31: 2000 | B31: =A31*Assumptions!$B$14 | C31: =Assumptions!$B$20+B31*Assumptions!$B$33+A31*Assumptions!$B$34+A31*Assumptions!$B$40+A31*Assumptions!$B$41 | D31: =B31-C31 | E31: =IF(B31>0,D31/B31,0) | F31: =D31*12 | G31: =IF(D31<0,"Loss",IF(D31<20,"Break-even",IF(D31<500,"Growing","Profitable")))
A32: 5000 | B32: =A32*Assumptions!$B$14 | C32: =Assumptions!$B$20+B32*Assumptions!$B$33+A32*Assumptions!$B$34+A32*Assumptions!$B$40+A32*Assumptions!$B$41 | D32: =B32-C32 | E32: =IF(B32>0,D32/B32,0) | F32: =D32*12 | G32: =IF(D32<0,"Loss",IF(D32<20,"Break-even",IF(D32<500,"Growing","Profitable")))
A34: CREATOR TIER — £7/mo per user
A35: Users | B35: Monthly Revenue | C35: Total Costs | D35: Net Profit | E35: Margin | F35: Annual Profit | G35: Status
A36: 1 | B36: =A36*Assumptions!$B$6 | C36: =Assumptions!$B$20+B36*Assumptions!$B$33+A36*Assumptions!$B$34+A36*Assumptions!$B$25+A36*Assumptions!$B$26 | D36: =B36-C36 | E36: =IF(B36>0,D36/B36,0) | F36: =D36*12 | G36: =IF(D36<0,"Loss",IF(D36<20,"Break-even",IF(D36<500,"Growing","Profitable")))
A37: 5 | B37: =A37*Assumptions!$B$6 | C37: =Assumptions!$B$20+B37*Assumptions!$B$33+A37*Assumptions!$B$34+A37*Assumptions!$B$25+A37*Assumptions!$B$26 | D37: =B37-C37 | E37: =IF(B37>0,D37/B37,0) | F37: =D37*12 | G37: =IF(D37<0,"Loss",IF(D37<20,"Break-even",IF(D37<500,"Growing","Profitable")))
A38: 10 | B38: =A38*Assumptions!$B$6 | C38: =Assumptions!$B$20+B38*Assumptions!$B$33+A38*Assumptions!$B$34+A38*Assumptions!$B$25+A38*Assumptions!$B$26 | D38: =B38-C38 | E38: =IF(B38>0,D38/B38,0) | F38: =D38*12 | G38: =IF(D38<0,"Loss",IF(D38<20,"Break-even",IF(D38<500,"Growing","Profitable")))
A39: 15 | B39: =A39*Assumptions!$B$6 | C39: =Assumptions!$B$20+B39*Assumptions!$B$33+A39*Assumptions!$B$34+A39*Assumptions!$B$25+A39*Assumptions!$B$26 | D39: =B39-C39 | E39: =IF(B39>0,D39/B39,0) | F39: =D39*12 | G39: =IF(D39<0,"Loss",IF(D39<20,"Break-even",IF(D39<500,"Growing","Profitable")))
A40: 20 | B40: =A40*Assumptions!$B$6 | C40: =Assumptions!$B$20+B40*Assumptions!$B$33+A40*Assumptions!$B$34+A40*Assumptions!$B$25+A40*Assumptions!$B$26 | D40: =B40-C40 | E40: =IF(B40>0,D40/B40,0) | F40: =D40*12 | G40: =IF(D40<0,"Loss",IF(D40<20,"Break-even",IF(D40<500,"Growing","Profitable")))
A41: 50 | B41: =A41*Assumptions!$B$6 | C41: =Assumptions!$B$20+B41*Assumptions!$B$33+A41*Assumptions!$B$34+A41*Assumptions!$B$25+A41*Assumptions!$B$26 | D41: =B41-C41 | E41: =IF(B41>0,D41/B41,0) | F41: =D41*12 | G41: =IF(D41<0,"Loss",IF(D41<20,"Break-even",IF(D41<500,"Growing","Profitable")))
A42: 100 | B42: =A42*Assumptions!$B$6 | C42: =Assumptions!$B$20+B42*Assumptions!$B$33+A42*Assumptions!$B$34+A42*Assumptions!$B$25+A42*Assumptions!$B$26 | D42: =B42-C42 | E42: =IF(B42>0,D42/B42,0) | F42: =D42*12 | G42: =IF(D42<0,"Loss",IF(D42<20,"Break-even",IF(D42<500,"Growing","Profitable")))
A43: 200 | B43: =A43*Assumptions!$B$6 | C43: =Assumptions!$B$20+B43*Assumptions!$B$33+A43*Assumptions!$B$34+A43*Assumptions!$B$25+A43*Assumptions!$B$26 | D43: =B43-C43 | E43: =IF(B43>0,D43/B43,0) | F43: =D43*12 | G43: =IF(D43<0,"Loss",IF(D43<20,"Break-even",IF(D43<500,"Growing","Profitable")))
...

Sheet Assumptions
A1: YT Transcriber — Financial Model Assumptions
A2: Model C: Explorer (free trial) / Creator / Studio / Enterprise | 13 June 2026
A4: Assumption | B4: Value | C4: Notes
A5: ── TIER PRICING ──
A6: Creator monthly price | B6: 7 | C6: £7.00/mo — entry paid tier
A7: Studio monthly price | B7: 19 | C7: £19.00/mo — intended sweet spot
A8: Enterprise monthly price | B8: 45 | C8: £45.00/mo — team & power users
A10: ── TIER MIX (% of paying users) ──
A11: Creator share | B11: 0.2 | C11: 20% of paying users — update from real data when available
A12: Studio share | B12: 0.55 | C12: 55% of paying users — intended sweet spot
A13: Enterprise share | B13: 0.25 | C13: 25% of paying users
A14: Blended ARPU (auto) | B14: =$B$6*$B$11+$B$7*$B$12+$B$8*$B$13 | C14: Weighted avg revenue per paying user — updates automatically
A16: ── FIXED MONTHLY COSTS ──
A17: Vercel Pro (hosting) | B17: 16 | C17: Next.js hosting — Vercel Pro plan
A18: Supabase Pro (database) | B18: 20 | C18: Managed Postgres — required for commercial use
A19: Domain & SSL (amortised) | B19: 1.25 | C19: ~£15/year domain, amortised monthly
A20: Total fixed costs (auto) | B20: =$B$17+$B$18+$B$19 | C20: Sum of all fixed costs — applies regardless of user count
A22: ── VARIABLE COSTS (per user / month) ──
A23: Explorer variable cost | B23: 0.005 | C23: Storage & bandwidth for 3 trial videos — no AI, no screenshots
A24: Explorer AI cost | B24: 0 | C24: No AI on Explorer/trial tier
A25: Creator variable cost | B25: 0.01 | C25: Storage, bandwidth — no AI on Creator
A26: Creator AI cost | B26: 0 | C26: No AI features on Creator tier
A27: Studio variable cost | B27: 0.02 | C27: Storage + bandwidth
A28: Studio AI cost | B28: 0.016 | C28: 40% adoption × 4 vids/mo × £0.01 Haiku per use
A29: Enterprise variable cost | B29: 0.04 | C29: Higher storage & bandwidth
A30: Enterprise AI cost | B30: 0.04 | C30: 50% adoption × 8 vids/mo × £0.01 Haiku per use
A32: ── PAYMENT PROCESSING (paid tiers only) ──
A33: Stripe percentage fee | B33: 0.022 | C33: Stripe 1.5% + Clerk 0.7% overhead — Explorer pays nothing
A34: Per-transaction fee (£) | B34: 0.2 | C34: £0.20 per monthly subscription — not charged on Explorer
A36: ── CLERK AUTH ──
A37: Clerk monthly cost | B37: 0 | C37: Free up to 10,000 MAU — revisit at scale
A39: ── BLENDED MIX HELPERS (auto-calculated) ──
A40: Blended variable/user (auto) | B40: =$B$25*$B$11+$B$27*$B$12+$B$29*$B$13 | C40: Weighted variable cost across paying tier mix
A41: Blended AI cost/user (auto) | B41: =$B$26*$B$11+$B$28*$B$12+$B$30*$B$13 | C41: Weighted AI cost across paying tier mix
A43: ── NOT YET MODELLED ──
A44: Top-up credit revenue | B44: TBD | C44: £2.50 per +5 video pack — est. 20% Creator uptake — add when live
A45: Feature add-on revenue | B45: TBD | C45: Per-feature purchases on Creator — not yet priced
A46: Annual plan discount | B46: TBD | C46: ~15-20% discount for annual pre-pay — future option
A48: Yellow cells = editable inputs you can change. Blue/purple cells = auto-calculated (do not edit). Orange cells = not yet modelled.

Sheet Explorer Tier
A1: YT Transcriber — Explorer Tier
A2: Free trial — 3 videos total, no revenue, no Stripe fees — shows cost of running free users | 13 June 2026
A3: Users | B3: Revenue (£) | C3: Fixed Costs (£) | D3: Stripe Fees (£) | E3: Variable (£) | F3: AI Costs (£) | G3: Total Costs (£) | H3: Net Profit (£) | I3: Margin (%) | J3: Annual Run Rate (£) | K3: Status
A4: 1 | B4: =0 | C4: =Assumptions!$B$20 | D4: =0 | E4: =A4*Assumptions!$B$23 | F4: =A4*Assumptions!$B$24 | G4: =C4+D4+E4+F4 | H4: =B4-G4 | I4: =IF(B4>0,H4/B4,0) | J4: =H4*12 | K4: =IF(H4<0,"Loss",IF(H4<20,"Break-even",IF(H4<500,"Growing","Profitable")))
A5: 5 | B5: =0 | C5: =Assumptions!$B$20 | D5: =0 | E5: =A5*Assumptions!$B$23 | F5: =A5*Assumptions!$B$24 | G5: =C5+D5+E5+F5 | H5: =B5-G5 | I5: =IF(B5>0,H5/B5,0) | J5: =H5*12 | K5: =IF(H5<0,"Loss",IF(H5<20,"Break-even",IF(H5<500,"Growing","Profitable")))
A6: 10 | B6: =0 | C6: =Assumptions!$B$20 | D6: =0 | E6: =A6*Assumptions!$B$23 | F6: =A6*Assumptions!$B$24 | G6: =C6+D6+E6+F6 | H6: =B6-G6 | I6: =IF(B6>0,H6/B6,0) | J6: =H6*12 | K6: =IF(H6<0,"Loss",IF(H6<20,"Break-even",IF(H6<500,"Growing","Profitable")))
A7: 15 | B7: =0 | C7: =Assumptions!$B$20 | D7: =0 | E7: =A7*Assumptions!$B$23 | F7: =A7*Assumptions!$B$24 | G7: =C7+D7+E7+F7 | H7: =B7-G7 | I7: =IF(B7>0,H7/B7,0) | J7: =H7*12 | K7: =IF(H7<0,"Loss",IF(H7<20,"Break-even",IF(H7<500,"Growing","Profitable")))
A8: 20 | B8: =0 | C8: =Assumptions!$B$20 | D8: =0 | E8: =A8*Assumptions!$B$23 | F8: =A8*Assumptions!$B$24 | G8: =C8+D8+E8+F8 | H8: =B8-G8 | I8: =IF(B8>0,H8/B8,0) | J8: =H8*12 | K8: =IF(H8<0,"Loss",IF(H8<20,"Break-even",IF(H8<500,"Growing","Profitable")))
A9: 50 | B9: =0 | C9: =Assumptions!$B$20 | D9: =0 | E9: =A9*Assumptions!$B$23 | F9: =A9*Assumptions!$B$24 | G9: =C9+D9+E9+F9 | H9: =B9-G9 | I9: =IF(B9>0,H9/B9,0) | J9: =H9*12 | K9: =IF(H9<0,"Loss",IF(H9<20,"Break-even",IF(H9<500,"Growing","Profitable")))
A10: 100 | B10: =0 | C10: =Assumptions!$B$20 | D10: =0 | E10: =A10*Assumptions!$B$23 | F10: =A10*Assumptions!$B$24 | G10: =C10+D10+E10+F10 | H10: =B10-G10 | I10: =IF(B10>0,H10/B10,0) | J10: =H10*12 | K10: =IF(H10<0,"Loss",IF(H10<20,"Break-even",IF(H10<500,"Growing","Profitable")))
A11: 200 | B11: =0 | C11: =Assumptions!$B$20 | D11: =0 | E11: =A11*Assumptions!$B$23 | F11: =A11*Assumptions!$B$24 | G11: =C11+D11+E11+F11 | H11: =B11-G11 | I11: =IF(B11>0,H11/B11,0) | J11: =H11*12 | K11: =IF(H11<0,"Loss",IF(H11<20,"Break-even",IF(H11<500,"Growing","Profitable")))
A12: 500 | B12: =0 | C12: =Assumptions!$B$20 | D12: =0 | E12: =A12*Assumptions!$B$23 | F12: =A12*Assumptions!$B$24 | G12: =C12+D12+E12+F12 | H12: =B12-G12 | I12: =IF(B12>0,H12/B12,0) | J12: =H12*12 | K12: =IF(H12<0,"Loss",IF(H12<20,"Break-even",IF(H12<500,"Growing","Profitable")))
A13: 1000 | B13: =0 | C13: =Assumptions!$B$20 | D13: =0 | E13: =A13*Assumptions!$B$23 | F13: =A13*Assumptions!$B$24 | G13: =C13+D13+E13+F13 | H13: =B13-G13 | I13: =IF(B13>0,H13/B13,0) | J13: =H13*12 | K13: =IF(H13<0,"Loss",IF(H13<20,"Break-even",IF(H13<500,"Growing","Profitable")))
A14: 2000 | B14: =0 | C14: =Assumptions!$B$20 | D14: =0 | E14: =A14*Assumptions!$B$23 | F14: =A14*Assumptions!$B$24 | G14: =C14+D14+E14+F14 | H14: =B14-G14 | I14: =IF(B14>0,H14/B14,0) | J14: =H14*12 | K14: =IF(H14<0,"Loss",IF(H14<20,"Break-even",IF(H14<500,"Growing","Profitable")))
A15: 5000 | B15: =0 | C15: =Assumptions!$B$20 | D15: =0 | E15: =A15*Assumptions!$B$23 | F15: =A15*Assumptions!$B$24 | G15: =C15+D15+E15+F15 | H15: =B15-G15 | I15: =IF(B15>0,H15/B15,0) | J15: =H15*12 | K15: =IF(H15<0,"Loss",IF(H15<20,"Break-even",IF(H15<500,"Growing","Profitable")))
A17: Explorer is the free trial tier — Revenue and Stripe fees are always £0. Fixed infrastructure costs still apply. This section shows the net cost of running free/trial users. Variable cost per user reflects storage & bandwidth for up to 3 trial video transcriptions.

Sheet Creator Tier
A1: YT Transcriber — Creator Tier
A2: Entry paid tier — 15 videos/mo, core transcript features, no AI, no screenshots in ZIP | 13 June 2026
A3: Users | B3: Revenue (£) | C3: Fixed Costs (£) | D3: Stripe Fees (£) | E3: Variable (£) | F3: AI Costs (£) | G3: Total Costs (£) | H3: Net Profit (£) | I3: Margin (%) | J3: Annual Run Rate (£) | K3: Status
A4: 1 | B4: =A4*Assumptions!$B$6 | C4: =Assumptions!$B$20 | D4: =B4*Assumptions!$B$33+A4*Assumptions!$B$34 | E4: =A4*Assumptions!$B$25 | F4: =A4*Assumptions!$B$26 | G4: =C4+D4+E4+F4 | H4: =B4-G4 | I4: =IF(B4>0,H4/B4,0) | J4: =H4*12 | K4: =IF(H4<0,"Loss",IF(H4<20,"Break-even",IF(H4<500,"Growing","Profitable")))
A5: 5 | B5: =A5*Assumptions!$B$6 | C5: =Assumptions!$B$20 | D5: =B5*Assumptions!$B$33+A5*Assumptions!$B$34 | E5: =A5*Assumptions!$B$25 | F5: =A5*Assumptions!$B$26 | G5: =C5+D5+E5+F5 | H5: =B5-G5 | I5: =IF(B5>0,H5/B5,0) | J5: =H5*12 | K5: =IF(H5<0,"Loss",IF(H5<20,"Break-even",IF(H5<500,"Growing","Profitable")))
A6: 10 | B6: =A6*Assumptions!$B$6 | C6: =Assumptions!$B$20 | D6: =B6*Assumptions!$B$33+A6*Assumptions!$B$34 | E6: =A6*Assumptions!$B$25 | F6: =A6*Assumptions!$B$26 | G6: =C6+D6+E6+F6 | H6: =B6-G6 | I6: =IF(B6>0,H6/B6,0) | J6: =H6*12 | K6: =IF(H6<0,"Loss",IF(H6<20,"Break-even",IF(H6<500,"Growing","Profitable")))
A7: 15 | B7: =A7*Assumptions!$B$6 | C7: =Assumptions!$B$20 | D7: =B7*Assumptions!$B$33+A7*Assumptions!$B$34 | E7: =A7*Assumptions!$B$25 | F7: =A7*Assumptions!$B$26 | G7: =C7+D7+E7+F7 | H7: =B7-G7 | I7: =IF(B7>0,H7/B7,0) | J7: =H7*12 | K7: =IF(H7<0,"Loss",IF(H7<20,"Break-even",IF(H7<500,"Growing","Profitable")))
A8: 20 | B8: =A8*Assumptions!$B$6 | C8: =Assumptions!$B$20 | D8: =B8*Assumptions!$B$33+A8*Assumptions!$B$34 | E8: =A8*Assumptions!$B$25 | F8: =A8*Assumptions!$B$26 | G8: =C8+D8+E8+F8 | H8: =B8-G8 | I8: =IF(B8>0,H8/B8,0) | J8: =H8*12 | K8: =IF(H8<0,"Loss",IF(H8<20,"Break-even",IF(H8<500,"Growing","Profitable")))
A9: 50 | B9: =A9*Assumptions!$B$6 | C9: =Assumptions!$B$20 | D9: =B9*Assumptions!$B$33+A9*Assumptions!$B$34 | E9: =A9*Assumptions!$B$25 | F9: =A9*Assumptions!$B$26 | G9: =C9+D9+E9+F9 | H9: =B9-G9 | I9: =IF(B9>0,H9/B9,0) | J9: =H9*12 | K9: =IF(H9<0,"Loss",IF(H9<20,"Break-even",IF(H9<500,"Growing","Profitable")))
A10: 100 | B10: =A10*Assumptions!$B$6 | C10: =Assumptions!$B$20 | D10: =B10*Assumptions!$B$33+A10*Assumptions!$B$34 | E10: =A10*Assumptions!$B$25 | F10: =A10*Assumptions!$B$26 | G10: =C10+D10+E10+F10 | H10: =B10-G10 | I10: =IF(B10>0,H10/B10,0) | J10: =H10*12 | K10: =IF(H10<0,"Loss",IF(H10<20,"Break-even",IF(H10<500,"Growing","Profitable")))
A11: 200 | B11: =A11*Assumptions!$B$6 | C11: =Assumptions!$B$20 | D11: =B11*Assumptions!$B$33+A11*Assumptions!$B$34 | E11: =A11*Assumptions!$B$25 | F11: =A11*Assumptions!$B$26 | G11: =C11+D11+E11+F11 | H11: =B11-G11 | I11: =IF(B11>0,H11/B11,0) | J11: =H11*12 | K11: =IF(H11<0,"Loss",IF(H11<20,"Break-even",IF(H11<500,"Growing","Profitable")))
A12: 500 | B12: =A12*Assumptions!$B$6 | C12: =Assumptions!$B$20 | D12: =B12*Assumptions!$B$33+A12*Assumptions!$B$34 | E12: =A12*Assumptions!$B$25 | F12: =A12*Assumptions!$B$26 | G12: =C12+D12+E12+F12 | H12: =B12-G12 | I12: =IF(B12>0,H12/B12,0) | J12: =H12*12 | K12: =IF(H12<0,"Loss",IF(H12<20,"Break-even",IF(H12<500,"Growing","Profitable")))
A13: 1000 | B13: =A13*Assumptions!$B$6 | C13: =Assumptions!$B$20 | D13: =B13*Assumptions!$B$33+A13*Assumptions!$B$34 | E13: =A13*Assumptions!$B$25 | F13: =A13*Assumptions!$B$26 | G13: =C13+D13+E13+F13 | H13: =B13-G13 | I13: =IF(B13>0,H13/B13,0) | J13: =H13*12 | K13: =IF(H13<0,"Loss",IF(H13<20,"Break-even",IF(H13<500,"Growing","Profitable")))
A14: 2000 | B14: =A14*Assumptions!$B$6 | C14: =Assumptions!$B$20 | D14: =B14*Assumptions!$B$33+A14*Assumptions!$B$34 | E14: =A14*Assumptions!$B$25 | F14: =A14*Assumptions!$B$26 | G14: =C14+D14+E14+F14 | H14: =B14-G14 | I14: =IF(B14>0,H14/B14,0) | J14: =H14*12 | K14: =IF(H14<0,"Loss",IF(H14<20,"Break-even",IF(H14<500,"Growing","Profitable")))
A15: 5000 | B15: =A15*Assumptions!$B$6 | C15: =Assumptions!$B$20 | D15: =B15*Assumptions!$B$33+A15*Assumptions!$B$34 | E15: =A15*Assumptions!$B$25 | F15: =A15*Assumptions!$B$26 | G15: =C15+D15+E15+F15 | H15: =B15-G15 | I15: =IF(B15>0,H15/B15,0) | J15: =H15*12 | K15: =IF(H15<0,"Loss",IF(H15<20,"Break-even",IF(H15<500,"Growing","Profitable")))
A17: All values driven by Assumptions sheet. Edit yellow input cells there and this sheet updates automatically. Fixed costs are shared infrastructure costs that apply regardless of how many users are on this tier.

Sheet Studio Tier
A1: YT Transcriber — Studio Tier
A2: Sweet spot — 60 videos/mo, all features, AI chapters included | 13 June 2026
A3: Users | B3: Revenue (£) | C3: Fixed Costs (£) | D3: Stripe Fees (£) | E3: Variable (£) | F3: AI Costs (£) | G3: Total Costs (£) | H3: Net Profit (£) | I3: Margin (%) | J3: Annual Run Rate (£) | K3: Status
A4: 1 | B4: =A4*Assumptions!$B$7 | C4: =Assumptions!$B$20 | D4: =B4*Assumptions!$B$33+A4*Assumptions!$B$34 | E4: =A4*Assumptions!$B$27 | F4: =A4*Assumptions!$B$28 | G4: =C4+D4+E4+F4 | H4: =B4-G4 | I4: =IF(B4>0,H4/B4,0) | J4: =H4*12 | K4: =IF(H4<0,"Loss",IF(H4<20,"Break-even",IF(H4<500,"Growing","Profitable")))
A5: 5 | B5: =A5*Assumptions!$B$7 | C5: =Assumptions!$B$20 | D5: =B5*Assumptions!$B$33+A5*Assumptions!$B$34 | E5: =A5*Assumptions!$B$27 | F5: =A5*Assumptions!$B$28 | G5: =C5+D5+E5+F5 | H5: =B5-G5 | I5: =IF(B5>0,H5/B5,0) | J5: =H5*12 | K5: =IF(H5<0,"Loss",IF(H5<20,"Break-even",IF(H5<500,"Growing","Profitable")))
A6: 10 | B6: =A6*Assumptions!$B$7 | C6: =Assumptions!$B$20 | D6: =B6*Assumptions!$B$33+A6*Assumptions!$B$34 | E6: =A6*Assumptions!$B$27 | F6: =A6*Assumptions!$B$28 | G6: =C6+D6+E6+F6 | H6: =B6-G6 | I6: =IF(B6>0,H6/B6,0) | J6: =H6*12 | K6: =IF(H6<0,"Loss",IF(H6<20,"Break-even",IF(H6<500,"Growing","Profitable")))
A7: 15 | B7: =A7*Assumptions!$B$7 | C7: =Assumptions!$B$20 | D7: =B7*Assumptions!$B$33+A7*Assumptions!$B$34 | E7: =A7*Assumptions!$B$27 | F7: =A7*Assumptions!$B$28 | G7: =C7+D7+E7+F7 | H7: =B7-G7 | I7: =IF(B7>0,H7/B7,0) | J7: =H7*12 | K7: =IF(H7<0,"Loss",IF(H7<20,"Break-even",IF(H7<500,"Growing","Profitable")))
A8: 20 | B8: =A8*Assumptions!$B$7 | C8: =Assumptions!$B$20 | D8: =B8*Assumptions!$B$33+A8*Assumptions!$B$34 | E8: =A8*Assumptions!$B$27 | F8: =A8*Assumptions!$B$28 | G8: =C8+D8+E8+F8 | H8: =B8-G8 | I8: =IF(B8>0,H8/B8,0) | J8: =H8*12 | K8: =IF(H8<0,"Loss",IF(H8<20,"Break-even",IF(H8<500,"Growing","Profitable")))
A9: 50 | B9: =A9*Assumptions!$B$7 | C9: =Assumptions!$B$20 | D9: =B9*Assumptions!$B$33+A9*Assumptions!$B$34 | E9: =A9*Assumptions!$B$27 | F9: =A9*Assumptions!$B$28 | G9: =C9+D9+E9+F9 | H9: =B9-G9 | I9: =IF(B9>0,H9/B9,0) | J9: =H9*12 | K9: =IF(H9<0,"Loss",IF(H9<20,"Break-even",IF(H9<500,"Growing","Profitable")))
A10: 100 | B10: =A10*Assumptions!$B$7 | C10: =Assumptions!$B$20 | D10: =B10*Assumptions!$B$33+A10*Assumptions!$B$34 | E10: =A10*Assumptions!$B$27 | F10: =A10*Assumptions!$B$28 | G10: =C10+D10+E10+F10 | H10: =B10-G10 | I10: =IF(B10>0,H10/B10,0) | J10: =H10*12 | K10: =IF(H10<0,"Loss",IF(H10<20,"Break-even",IF(H10<500,"Growing","Profitable")))
A11: 200 | B11: =A11*Assumptions!$B$7 | C11: =Assumptions!$B$20 | D11: =B11*Assumptions!$B$33+A11*Assumptions!$B$34 | E11: =A11*Assumptions!$B$27 | F11: =A11*Assumptions!$B$28 | G11: =C11+D11+E11+F11 | H11: =B11-G11 | I11: =IF(B11>0,H11/B11,0) | J11: =H11*12 | K11: =IF(H11<0,"Loss",IF(H11<20,"Break-even",IF(H11<500,"Growing","Profitable")))
A12: 500 | B12: =A12*Assumptions!$B$7 | C12: =Assumptions!$B$20 | D12: =B12*Assumptions!$B$33+A12*Assumptions!$B$34 | E12: =A12*Assumptions!$B$27 | F12: =A12*Assumptions!$B$28 | G12: =C12+D12+E12+F12 | H12: =B12-G12 | I12: =IF(B12>0,H12/B12,0) | J12: =H12*12 | K12: =IF(H12<0,"Loss",IF(H12<20,"Break-even",IF(H12<500,"Growing","Profitable")))
A13: 1000 | B13: =A13*Assumptions!$B$7 | C13: =Assumptions!$B$20 | D13: =B13*Assumptions!$B$33+A13*Assumptions!$B$34 | E13: =A13*Assumptions!$B$27 | F13: =A13*Assumptions!$B$28 | G13: =C13+D13+E13+F13 | H13: =B13-G13 | I13: =IF(B13>0,H13/B13,0) | J13: =H13*12 | K13: =IF(H13<0,"Loss",IF(H13<20,"Break-even",IF(H13<500,"Growing","Profitable")))
A14: 2000 | B14: =A14*Assumptions!$B$7 | C14: =Assumptions!$B$20 | D14: =B14*Assumptions!$B$33+A14*Assumptions!$B$34 | E14: =A14*Assumptions!$B$27 | F14: =A14*Assumptions!$B$28 | G14: =C14+D14+E14+F14 | H14: =B14-G14 | I14: =IF(B14>0,H14/B14,0) | J14: =H14*12 | K14: =IF(H14<0,"Loss",IF(H14<20,"Break-even",IF(H14<500,"Growing","Profitable")))
A15: 5000 | B15: =A15*Assumptions!$B$7 | C15: =Assumptions!$B$20 | D15: =B15*Assumptions!$B$33+A15*Assumptions!$B$34 | E15: =A15*Assumptions!$B$27 | F15: =A15*Assumptions!$B$28 | G15: =C15+D15+E15+F15 | H15: =B15-G15 | I15: =IF(B15>0,H15/B15,0) | J15: =H15*12 | K15: =IF(H15<0,"Loss",IF(H15<20,"Break-even",IF(H15<500,"Growing","Profitable")))
A17: All values driven by Assumptions sheet. Edit yellow input cells there and this sheet updates automatically. Fixed costs are shared infrastructure costs that apply regardless of how many users are on this tier.

Sheet Enterprise Tier
A1: YT Transcriber — Enterprise Tier
A2: Power tier — Unlimited videos, team workspace, priority processing | 13 June 2026
A3: Users | B3: Revenue (£) | C3: Fixed Costs (£) | D3: Stripe Fees (£) | E3: Variable (£) | F3: AI Costs (£) | G3: Total Costs (£) | H3: Net Profit (£) | I3: Margin (%) | J3: Annual Run Rate (£) | K3: Status
A4: 1 | B4: =A4*Assumptions!$B$8 | C4: =Assumptions!$B$20 | D4: =B4*Assumptions!$B$33+A4*Assumptions!$B$34 | E4: =A4*Assumptions!$B$29 | F4: =A4*Assumptions!$B$30 | G4: =C4+D4+E4+F4 | H4: =B4-G4 | I4: =IF(B4>0,H4/B4,0) | J4: =H4*12 | K4: =IF(H4<0,"Loss",IF(H4<20,"Break-even",IF(H4<500,"Growing","Profitable")))
A5: 5 | B5: =A5*Assumptions!$B$8 | C5: =Assumptions!$B$20 | D5: =B5*Assumptions!$B$33+A5*Assumptions!$B$34 | E5: =A5*Assumptions!$B$29 | F5: =A5*Assumptions!$B$30 | G5: =C5+D5+E5+F5 | H5: =B5-G5 | I5: =IF(B5>0,H5/B5,0) | J5: =H5*12 | K5: =IF(H5<0,"Loss",IF(H5<20,"Break-even",IF(H5<500,"Growing","Profitable")))
A6: 10 | B6: =A6*Assumptions!$B$8 | C6: =Assumptions!$B$20 | D6: =B6*Assumptions!$B$33+A6*Assumptions!$B$34 | E6: =A6*Assumptions!$B$29 | F6: =A6*Assumptions!$B$30 | G6: =C6+D6+E6+F6 | H6: =B6-G6 | I6: =IF(B6>0,H6/B6,0) | J6: =H6*12 | K6: =IF(H6<0,"Loss",IF(H6<20,"Break-even",IF(H6<500,"Growing","Profitable")))
A7: 15 | B7: =A7*Assumptions!$B$8 | C7: =Assumptions!$B$20 | D7: =B7*Assumptions!$B$33+A7*Assumptions!$B$34 | E7: =A7*Assumptions!$B$29 | F7: =A7*Assumptions!$B$30 | G7: =C7+D7+E7+F7 | H7: =B7-G7 | I7: =IF(B7>0,H7/B7,0) | J7: =H7*12 | K7: =IF(H7<0,"Loss",IF(H7<20,"Break-even",IF(H7<500,"Growing","Profitable")))
A8: 20 | B8: =A8*Assumptions!$B$8 | C8: =Assumptions!$B$20 | D8: =B8*Assumptions!$B$33+A8*Assumptions!$B$34 | E8: =A8*Assumptions!$B$29 | F8: =A8*Assumptions!$B$30 | G8: =C8+D8+E8+F8 | H8: =B8-G8 | I8: =IF(B8>0,H8/B8,0) | J8: =H8*12 | K8: =IF(H8<0,"Loss",IF(H8<20,"Break-even",IF(H8<500,"Growing","Profitable")))
A9: 50 | B9: =A9*Assumptions!$B$8 | C9: =Assumptions!$B$20 | D9: =B9*Assumptions!$B$33+A9*Assumptions!$B$34 | E9: =A9*Assumptions!$B$29 | F9: =A9*Assumptions!$B$30 | G9: =C9+D9+E9+F9 | H9: =B9-G9 | I9: =IF(B9>0,H9/B9,0) | J9: =H9*12 | K9: =IF(H9<0,"Loss",IF(H9<20,"Break-even",IF(H9<500,"Growing","Profitable")))
A10: 100 | B10: =A10*Assumptions!$B$8 | C10: =Assumptions!$B$20 | D10: =B10*Assumptions!$B$33+A10*Assumptions!$B$34 | E10: =A10*Assumptions!$B$29 | F10: =A10*Assumptions!$B$30 | G10: =C10+D10+E10+F10 | H10: =B10-G10 | I10: =IF(B10>0,H10/B10,0) | J10: =H10*12 | K10: =IF(H10<0,"Loss",IF(H10<20,"Break-even",IF(H10<500,"Growing","Profitable")))
A11: 200 | B11: =A11*Assumptions!$B$8 | C11: =Assumptions!$B$20 | D11: =B11*Assumptions!$B$33+A11*Assumptions!$B$34 | E11: =A11*Assumptions!$B$29 | F11: =A11*Assumptions!$B$30 | G11: =C11+D11+E11+F11 | H11: =B11-G11 | I11: =IF(B11>0,H11/B11,0) | J11: =H11*12 | K11: =IF(H11<0,"Loss",IF(H11<20,"Break-even",IF(H11<500,"Growing","Profitable")))
A12: 500 | B12: =A12*Assumptions!$B$8 | C12: =Assumptions!$B$20 | D12: =B12*Assumptions!$B$33+A12*Assumptions!$B$34 | E12: =A12*Assumptions!$B$29 | F12: =A12*Assumptions!$B$30 | G12: =C12+D12+E12+F12 | H12: =B12-G12 | I12: =IF(B12>0,H12/B12,0) | J12: =H12*12 | K12: =IF(H12<0,"Loss",IF(H12<20,"Break-even",IF(H12<500,"Growing","Profitable")))
A13: 1000 | B13: =A13*Assumptions!$B$8 | C13: =Assumptions!$B$20 | D13: =B13*Assumptions!$B$33+A13*Assumptions!$B$34 | E13: =A13*Assumptions!$B$29 | F13: =A13*Assumptions!$B$30 | G13: =C13+D13+E13+F13 | H13: =B13-G13 | I13: =IF(B13>0,H13/B13,0) | J13: =H13*12 | K13: =IF(H13<0,"Loss",IF(H13<20,"Break-even",IF(H13<500,"Growing","Profitable")))
A14: 2000 | B14: =A14*Assumptions!$B$8 | C14: =Assumptions!$B$20 | D14: =B14*Assumptions!$B$33+A14*Assumptions!$B$34 | E14: =A14*Assumptions!$B$29 | F14: =A14*Assumptions!$B$30 | G14: =C14+D14+E14+F14 | H14: =B14-G14 | I14: =IF(B14>0,H14/B14,0) | J14: =H14*12 | K14: =IF(H14<0,"Loss",IF(H14<20,"Break-even",IF(H14<500,"Growing","Profitable")))
A15: 5000 | B15: =A15*Assumptions!$B$8 | C15: =Assumptions!$B$20 | D15: =B15*Assumptions!$B$33+A15*Assumptions!$B$34 | E15: =A15*Assumptions!$B$29 | F15: =A15*Assumptions!$B$30 | G15: =C15+D15+E15+F15 | H15: =B15-G15 | I15: =IF(B15>0,H15/B15,0) | J15: =H15*12 | K15: =IF(H15<0,"Loss",IF(H15<20,"Break-even",IF(H15<500,"Growing","Profitable")))
A17: All values driven by Assumptions sheet. Edit yellow input cells there and this sheet updates automatically. Fixed costs are shared infrastructure costs that apply regardless of how many users are on this tier.

Sheet Blended Mix
A1: YT Transcriber — Blended Mix
A2: Paying users only — 20% Creator / 55% Studio / 25% Enterprise — adjust mix in Assumptions | 13 June 2026
A3: Users | B3: Revenue (£) | C3: Fixed Costs (£) | D3: Stripe Fees (£) | E3: Variable (£) | F3: AI Costs (£) | G3: Total Costs (£) | H3: Net Profit (£) | I3: Margin (%) | J3: Annual Run Rate (£) | K3: Status
A4: 1 | B4: =A4*Assumptions!$B$14 | C4: =Assumptions!$B$20 | D4: =B4*Assumptions!$B$33+A4*Assumptions!$B$34 | E4: =A4*Assumptions!$B$40 | F4: =A4*Assumptions!$B$41 | G4: =C4+D4+E4+F4 | H4: =B4-G4 | I4: =IF(B4>0,H4/B4,0) | J4: =H4*12 | K4: =IF(H4<0,"Loss",IF(H4<20,"Break-even",IF(H4<500,"Growing","Profitable")))
A5: 5 | B5: =A5*Assumptions!$B$14 | C5: =Assumptions!$B$20 | D5: =B5*Assumptions!$B$33+A5*Assumptions!$B$34 | E5: =A5*Assumptions!$B$40 | F5: =A5*Assumptions!$B$41 | G5: =C5+D5+E5+F5 | H5: =B5-G5 | I5: =IF(B5>0,H5/B5,0) | J5: =H5*12 | K5: =IF(H5<0,"Loss",IF(H5<20,"Break-even",IF(H5<500,"Growing","Profitable")))
A6: 10 | B6: =A6*Assumptions!$B$14 | C6: =Assumptions!$B$20 | D6: =B6*Assumptions!$B$33+A6*Assumptions!$B$34 | E6: =A6*Assumptions!$B$40 | F6: =A6*Assumptions!$B$41 | G6: =C6+D6+E6+F6 | H6: =B6-G6 | I6: =IF(B6>0,H6/B6,0) | J6: =H6*12 | K6: =IF(H6<0,"Loss",IF(H6<20,"Break-even",IF(H6<500,"Growing","Profitable")))
A7: 15 | B7: =A7*Assumptions!$B$14 | C7: =Assumptions!$B$20 | D7: =B7*Assumptions!$B$33+A7*Assumptions!$B$34 | E7: =A7*Assumptions!$B$40 | F7: =A7*Assumptions!$B$41 | G7: =C7+D7+E7+F7 | H7: =B7-G7 | I7: =IF(B7>0,H7/B7,0) | J7: =H7*12 | K7: =IF(H7<0,"Loss",IF(H7<20,"Break-even",IF(H7<500,"Growing","Profitable")))
A8: 20 | B8: =A8*Assumptions!$B$14 | C8: =Assumptions!$B$20 | D8: =B8*Assumptions!$B$33+A8*Assumptions!$B$34 | E8: =A8*Assumptions!$B$40 | F8: =A8*Assumptions!$B$41 | G8: =C8+D8+E8+F8 | H8: =B8-G8 | I8: =IF(B8>0,H8/B8,0) | J8: =H8*12 | K8: =IF(H8<0,"Loss",IF(H8<20,"Break-even",IF(H8<500,"Growing","Profitable")))
A9: 50 | B9: =A9*Assumptions!$B$14 | C9: =Assumptions!$B$20 | D9: =B9*Assumptions!$B$33+A9*Assumptions!$B$34 | E9: =A9*Assumptions!$B$40 | F9: =A9*Assumptions!$B$41 | G9: =C9+D9+E9+F9 | H9: =B9-G9 | I9: =IF(B9>0,H9/B9,0) | J9: =H9*12 | K9: =IF(H9<0,"Loss",IF(H9<20,"Break-even",IF(H9<500,"Growing","Profitable")))
A10: 100 | B10: =A10*Assumptions!$B$14 | C10: =Assumptions!$B$20 | D10: =B10*Assumptions!$B$33+A10*Assumptions!$B$34 | E10: =A10*Assumptions!$B$40 | F10: =A10*Assumptions!$B$41 | G10: =C10+D10+E10+F10 | H10: =B10-G10 | I10: =IF(B10>0,H10/B10,0) | J10: =H10*12 | K10: =IF(H10<0,"Loss",IF(H10<20,"Break-even",IF(H10<500,"Growing","Profitable")))
A11: 200 | B11: =A11*Assumptions!$B$14 | C11: =Assumptions!$B$20 | D11: =B11*Assumptions!$B$33+A11*Assumptions!$B$34 | E11: =A11*Assumptions!$B$40 | F11: =A11*Assumptions!$B$41 | G11: =C11+D11+E11+F11 | H11: =B11-G11 | I11: =IF(B11>0,H11/B11,0) | J11: =H11*12 | K11: =IF(H11<0,"Loss",IF(H11<20,"Break-even",IF(H11<500,"Growing","Profitable")))
A12: 500 | B12: =A12*Assumptions!$B$14 | C12: =Assumptions!$B$20 | D12: =B12*Assumptions!$B$33+A12*Assumptions!$B$34 | E12: =A12*Assumptions!$B$40 | F12: =A12*Assumptions!$B$41 | G12: =C12+D12+E12+F12 | H12: =B12-G12 | I12: =IF(B12>0,H12/B12,0) | J12: =H12*12 | K12: =IF(H12<0,"Loss",IF(H12<20,"Break-even",IF(H12<500,"Growing","Profitable")))
A13: 1000 | B13: =A13*Assumptions!$B$14 | C13: =Assumptions!$B$20 | D13: =B13*Assumptions!$B$33+A13*Assumptions!$B$34 | E13: =A13*Assumptions!$B$40 | F13: =A13*Assumptions!$B$41 | G13: =C13+D13+E13+F13 | H13: =B13-G13 | I13: =IF(B13>0,H13/B13,0) | J13: =H13*12 | K13: =IF(H13<0,"Loss",IF(H13<20,"Break-even",IF(H13<500,"Growing","Profitable")))
A14: 2000 | B14: =A14*Assumptions!$B$14 | C14: =Assumptions!$B$20 | D14: =B14*Assumptions!$B$33+A14*Assumptions!$B$34 | E14: =A14*Assumptions!$B$40 | F14: =A14*Assumptions!$B$41 | G14: =C14+D14+E14+F14 | H14: =B14-G14 | I14: =IF(B14>0,H14/B14,0) | J14: =H14*12 | K14: =IF(H14<0,"Loss",IF(H14<20,"Break-even",IF(H14<500,"Growing","Profitable")))
A15: 5000 | B15: =A15*Assumptions!$B$14 | C15: =Assumptions!$B$20 | D15: =B15*Assumptions!$B$33+A15*Assumptions!$B$34 | E15: =A15*Assumptions!$B$40 | F15: =A15*Assumptions!$B$41 | G15: =C15+D15+E15+F15 | H15: =B15-G15 | I15: =IF(B15>0,H15/B15,0) | J15: =H15*12 | K15: =IF(H15<0,"Loss",IF(H15<20,"Break-even",IF(H15<500,"Growing","Profitable")))
A17: All values driven by Assumptions sheet. Edit yellow input cells there and this sheet updates automatically. Fixed costs are shared infrastructure costs that apply regardless of how many users are on this tier.
